
<mujoco>
  <asset>
    <mesh name="robot_stl" file="robot_decimated.stl" scale="1 1 1"/>
  </asset>

  <worldbody>
    <!-- field plane -->
    <geom name="field" type="plane" size="7.5 6 0.01" pos="0 0 -0.01" rgba="0.48 0.78 0.27 1"/>

    <!-- Left Goal (starting at -6m) -->
    <body name="left_goal" pos="-6 0 0">
        <!-- Red goal line at exactly x=-6 -->
        <site name="left_goal_box" pos="-0.1 0 0" size="0.1 0.9 0.001" rgba="1 0 0 1" type="box"/>
        
        <!-- Side blockers -->
        <geom name="left_goal_side_top" type="box" size="0.1 0.01 0.09" pos="-0.1 0.9 0.09" rgba="0 0 1 1"/>
        <geom name="left_goal_side_bottom" type="box" size="0.1 0.01 0.09" pos="-0.1 -0.9 0.09" rgba="0 0 1 1"/>
        
        <!-- Backside -->
        <geom name="left_goal_backside" type="box" pos="-0.2 0 0.09" size="0.01 0.9 0.09" rgba="0 0 1 0.5"/>
    </body>

    <!-- Right Goal (starting at +6m) -->
    <body name="right_goal" pos="6 0 0">
        <!-- Red goal line at exactly x=6 -->
        <site name="right_goal_box" pos="0.1 0 0" size="0.1 0.9 0.001" rgba="1 0 0 1" type="box"/>
        
        <!-- Side blockers -->
        <geom name="right_goal_side_top" type="box" size="0.1 0.01 0.09" pos="0.1 0.9 0.09" rgba="0 0 1 1"/>
        <geom name="right_goal_side_bottom" type="box" size="0.1 0.01 0.09" pos="0.1 -0.9 0.09" rgba="0 0 1 1"/>
        
        <!-- Backside -->
        <geom name="right_goal_backside" type="box" pos="0.2 0 0.09" size="0.01 0.9 0.09" rgba="0 0 1 0.5"/>
    </body>

    <!-- Field boundary lines for 12×9 meter field -->
    <site name="field_line_north" pos="0 4.504 0" size="6 0.008 0.001" rgba="1 1 1 1" type="box"/>
    <site name="field_line_south" pos="0 -4.504 0" size="6 0.008 0.001" rgba="1 1 1 1" type="box"/>
    <site name="field_line_east" pos="6.008 0 0" size="0.008 4.5 0.001" rgba="1 1 1 1" type="box"/>
    <site name="field_line_west" pos="-6.008 0 0" size="0.008 4.5 0.001" rgba="1 1 1 1" type="box"/>

    <!-- Field lines middle-->
    <site name="field_line_vertical" pos="0 0 0" size="0.008 4.5 0.001" rgba="1 1 1 1" type="box"/>
    <site name="field_line_horizontal" pos="0 0 0" size="6 0.008 0.001" rgba="1 1 1 1" type="box"/>
                                                                                            
    <!-- Left goal box (1.8m wide × 3.6m tall) -->
    <site name="left_goal_box_top" pos="-5.1 1.8 0.0005" size="0.9 0.008 0.001" rgba="1 1 1 1" type="box"/>
    <site name="left_goal_box_bottom" pos="-5.1 -1.8 0.0005" size="0.9 0.008 0.001" rgba="1 1 1 1" type="box"/>
    <site name="left_goal_box_front" pos="-4.2 0 0.0005" size="0.008 1.8 0.001" rgba="1 1 1 1" type="box"/>

    <!-- Right goal box (1.8m wide × 3.6m tall) -->
    <site name="right_goal_box_top" pos="5.1 1.8 0.0005" size="0.9 0.008 0.001" rgba="1 1 1 1" type="box"/>
    <site name="right_goal_box_bottom" pos="5.1 -1.8 0.0005" size="0.9 0.008 0.001" rgba="1 1 1 1" type="box"/>
    <site name="right_goal_box_front" pos="4.2 0 0.0005" size="0.008 1.8 0.001" rgba="1 1 1 1" type="box"/>

    <!-- Body for main robot -->
    <body name="robot_planar" pos="0 0 0">
        <!-- Planar joint using a combination of slide joints -->
        <joint name="x_slide" type="slide" axis="1 0 0" pos="0 0 0" damping="0.8" armature="0.6"/>
        <joint name="y_slide" type="slide" axis="0 1 0" pos="0 0 0" damping="0.8" armature="0.6"/>
        <joint name="z_rotate" type="hinge" axis="0 0 1" pos="0 0 0" damping="0" armature="0.5"/>
            
        <!-- The actual robot geometry -->
        <geom name="robot_mesh" type="mesh" mesh="robot_stl" rgba="0 0 1 1" mass="5"/>

        <!-- Front-mounted kicker -->
        <body name="kicker_body" pos="0 0.065 0.02">
            <!-- Kicker joint -->
            <joint name="kicker_extend" type="slide" axis="0 1 0" limited="true" range="0 0.1"
                  damping="0" stiffness="0" armature="0"/>
            
            <!-- Kicker plate geometry -->
            <geom name="kicker_plate_geom" type="box" size="0.055 0.004 0.025" rgba="1 0.5 0 1" 
                  mass="0.5" friction="1.8 0.005 0.05" solref="0.01 1" solimp="0.95 0.98 0.001"/>
        </body>
    </body>

    <!-- Golf ball -->
    <body name="golf_ball" pos="0 1 1">
        <joint name= "ball_joint" type="free"/>                                                   
        <geom name="golf_ball_geom" type="sphere" size="0.0215" rgba="1 0 0 1" mass="0.046" friction="2.408 0.01 0.0035" condim="6"/> <!-- 0.0035 is set experimentally, sliding friction is rolling friction * 0.985 (from Tigers) -->
                                                                                                                                      <!-- However to model the friction of dribbler, make it times 8.-->
    </body>

  </worldbody>

    <actuator>
        <velocity name="x_vel" joint="x_slide" kv="22" ctrlrange="-3 3"/>
        <velocity name="y_vel" joint="y_slide" kv="22" ctrlrange="-3 3"/>
        <velocity name="rot_vel" joint="z_rotate" kv="5"/>

        <motor name="ball_x" joint="ball_joint" gear="0.5 0 0 0 0 0" />
        <motor name="ball_y" joint="ball_joint" gear="0 0.5 0 0 0 0" />
        <position name="kicker_pos" joint="kicker_extend" kp="800" kv="20" ctrlrange="0 1" ctrllimited="true"/>
  </actuator>

  <contact>
    <pair geom1="robot_mesh" geom2="golf_ball_geom"/>
    <pair geom1="kicker_plate_geom" geom2="golf_ball_geom"/>
    <exclude body1="robot_planar" body2="kicker_body"/>
</contact>

</mujoco>