
<mujoco>
  <asset>
    <mesh name="robot_stl" file="robot_decimated.stl" scale="1 1 1"/>
  </asset>

  <!-- <default>
    <geom contype="0" conaffinity="0"/>
  </default> -->

  <worldbody>
    <camera name="top" pos="0 0 12"/>                 

    <geom name="field" type="plane" size="7.5 6 0.01" pos="0 0 -0.01" rgba="0.48 0.78 0.27 1"/>

    <body name="left_goal" pos="-6 0 0">
        <site name="left_goal_box" pos="-0.1 0 0" size="0.1 0.9 0.001" rgba="1 0 0 1" type="box"/>
        <geom name="left_goal_side_top" type="box" size="0.1 0.01 0.09" pos="-0.1 0.9 0.09" rgba="0 0 1 1"/>
        <geom name="left_goal_side_bottom" type="box" size="0.1 0.01 0.09" pos="-0.1 -0.9 0.09" rgba="0 0 1 1"/>
        <geom name="left_goal_backside" type="box" pos="-0.2 0 0.09" size="0.01 0.9 0.09" rgba="0 0 1 0.5"/>
    </body>

    <body name="right_goal" pos="6 0 0">
        <site name="right_goal_box" pos="0.1 0 0" size="0.1 0.9 0.001" rgba="1 0 0 1" type="box"/>
        <geom name="right_goal_side_top" type="box" size="0.1 0.01 0.09" pos="0.1 0.9 0.09" rgba="0 0 1 1"/>
        <geom name="right_goal_side_bottom" type="box" size="0.1 0.01 0.09" pos="0.1 -0.9 0.09" rgba="0 0 1 1"/>
        <geom name="right_goal_backside" type="box" pos="0.2 0 0.09" size="0.01 0.9 0.09" rgba="0 0 1 0.5"/>
    </body>

    <site name="field_line_north" pos="0 4.504 0" size="6 0.008 0.001" rgba="1 1 1 1" type="box"/>
    <site name="field_line_south" pos="0 -4.504 0" size="6 0.008 0.001" rgba="1 1 1 1" type="box"/>
    <site name="field_line_east" pos="6.008 0 0" size="0.008 4.5 0.001" rgba="1 1 1 1" type="box"/>
    <site name="field_line_west" pos="-6.008 0 0" size="0.008 4.5 0.001" rgba="1 1 1 1" type="box"/>
    <site name="field_line_vertical" pos="0 0 0" size="0.008 4.5 0.001" rgba="1 1 1 1" type="box"/>
    <site name="field_line_horizontal" pos="0 0 0" size="6 0.008 0.001" rgba="1 1 1 1" type="box"/>
    <site name="left_goal_box_top" pos="-5.1 1.8 0.0005" size="0.9 0.008 0.001" rgba="1 1 1 1" type="box"/>
    <site name="left_goal_box_bottom" pos="-5.1 -1.8 0.0005" size="0.9 0.008 0.001" rgba="1 1 1 1" type="box"/>
    <site name="left_goal_box_front" pos="-4.2 0 0.0005" size="0.008 1.8 0.001" rgba="1 1 1 1" type="box"/>
    <site name="right_goal_box_top" pos="5.1 1.8 0.0005" size="0.9 0.008 0.001" rgba="1 1 1 1" type="box"/>
    <site name="right_goal_box_bottom" pos="5.1 -1.8 0.0005" size="0.9 0.008 0.001" rgba="1 1 1 1" type="box"/>
    <site name="right_goal_box_front" pos="4.2 0 0.0005" size="0.008 1.8 0.001" rgba="1 1 1 1" type="box"/>


    <body name="robot_planar_0" pos="-2 0 0">
        <joint name="x_slide_0" type="slide" axis="1 0 0" pos="0 0 0" damping="0.8" armature="0.6"/>
        <joint name="y_slide_0" type="slide" axis="0 1 0" pos="0 0 0" damping="0.8" armature="0.6"/>
        <joint name="z_rotate_0" type="hinge" axis="0 0 1" pos="0 0 0" damping="0" armature="0.5"/>

        <!-- <geom name="robot_mesh_0" type="mesh" mesh="robot_stl" rgba="0 0 1 1" mass="5"/> -->
        <geom name="robot_mesh_0" type="cylinder" size="0.15 0.02" pos="0 0 0.02" mass="5"/>

        <body name="kicker_body_0" pos="0 0.065 0.02">
            <joint name="kicker_extend_0" type="slide" axis="0 1 0" limited="true" range="0 0.1"
                  damping="0" stiffness="0" armature="0"/>

            <geom name="kicker_plate_geom_0" type="box" size="0.055 0.004 0.025" rgba="1 0.5 0 1"
                  mass="0.5" friction="1.8 0.005 0.05" solref="0.01 1" solimp="0.95 0.98 0.001"/>
        </body>
    </body>

    <body name="golf_ball" pos="0 0 0.0215"> <joint name= "ball_joint" type="free"/>
        <geom name="golf_ball_geom" type="sphere" size="0.0215" rgba="1 1 1 1" mass="0.046" friction="2.408 0.01 0.0035" condim="6"/>
    </body>

  </worldbody>

  <actuator>

    <velocity name="x_vel_0" joint="x_slide_0" kv="22" ctrlrange="-3 3"/>
    <velocity name="y_vel_0" joint="y_slide_0" kv="22" ctrlrange="-3 3"/>
    <velocity name="rot_vel_0" joint="z_rotate_0" kv="5"/>
    <position name="kicker_pos_0" joint="kicker_extend_0" kp="800" kv="20" ctrlrange="0 1" ctrllimited="true"/>

    </actuator>

  <contact>

    <pair geom1="robot_mesh_0" geom2="golf_ball_geom"/>
    <pair geom1="kicker_plate_geom_0" geom2="golf_ball_geom"/>
    <exclude body1="robot_planar_0" body2="kicker_body_0"/>

    </contact>

</mujoco>
