<mujoco model="robot_soccer_v2"> <option gravity="0 0 -9.81"
          timestep="0.002"
          solver="Newton"          iterations="5"           ls_iterations="10"       jacobian="dense">        <flag eulerdamp="disable"/>      </option>
  <default>
    <geom contype="0" conaffinity="0" group="1"/>
    <default class="visual">
       <geom contype="0" conaffinity="0" group="0"/> </default>
    <default class="collision">
        <geom contype="1" conaffinity="1" group="1" friction="0.7 0.1 0.1" solref="0.02 1" solimp="0.9 0.95 0.001"/> </default>
  </default>


  <asset>
    </asset>

  <visual>
    <global offwidth="1280" offheight="720"/>
    <map znear="0.01"/>
  </visual>

  <worldbody>
    <camera name="top" pos="0 0 15" zaxis="0 0 1"/>

    <geom name="field" type="plane" size="7.5 6 0.5" pos="0 0 0" class="collision" rgba="0.48 0.78 0.27 1"/>

    <body name="left_goal" pos="-6 0 0">
        <site name="left_goal_line" pos="-0.1 0 0.001" size="0.1 0.9 0.001" rgba="1 0 0 0.5" type="box" class="visual"/>
        <geom name="left_goal_side_top" type="box" size="0.1 0.01 0.09" pos="-0.1 0.9 0.09" class="collision" rgba="0.1 0.1 0.8 1"/>
        <geom name="left_goal_side_bottom" type="box" size="0.1 0.01 0.09" pos="-0.1 -0.9 0.09" class="collision" rgba="0.1 0.1 0.8 1"/>
        <geom name="left_goal_backside" type="box" pos="-0.2 0 0.09" size="0.01 0.9 0.09" class="collision" rgba="0.1 0.1 0.8 0.7"/>
    </body>
    <body name="right_goal" pos="6 0 0">
        <site name="right_goal_line" pos="0.1 0 0.001" size="0.1 0.9 0.001" rgba="1 0 0 0.5" type="box" class="visual"/>
        <geom name="right_goal_side_top" type="box" size="0.1 0.01 0.09" pos="0.1 0.9 0.09" class="collision" rgba="0.1 0.1 0.8 1"/>
        <geom name="right_goal_side_bottom" type="box" size="0.1 0.01 0.09" pos="0.1 -0.9 0.09" class="collision" rgba="0.1 0.1 0.8 1"/>
        <geom name="right_goal_backside" type="box" pos="0.2 0 0.09" size="0.01 0.9 0.09" class="collision" rgba="0.1 0.1 0.8 0.7"/>
    </body>

    <site name="field_line_north" pos="0 4.5 0.001" size="6 0.008 0.001" rgba="1 1 1 1" type="box" class="visual"/>
    <site name="field_line_south" pos="0 -4.5 0.001" size="6 0.008 0.001" rgba="1 1 1 1" type="box" class="visual"/>
    <site name="field_line_east" pos="6 0 0.001" size="0.008 4.5 0.001" rgba="1 1 1 1" type="box" class="visual"/>
    <site name="field_line_west" pos="-6 0 0.001" size="0.008 4.5 0.001" rgba="1 1 1 1" type="box" class="visual"/>
    <site name="field_line_center_vert" pos="0 0 0.001" size="0.008 4.5 0.001" rgba="1 1 1 1" type="box" class="visual"/> <site name="field_line_center_hor" pos="0 0 0.001" size="6 0.008 0.001" rgba="1 1 1 1" type="box" class="visual"/> <body name="robot_planar_0" pos="-2 0 0"> <joint name="x_slide_0" type="slide" axis="1 0 0" damping="1.0" armature="0.1" limited="false"/>
        <joint name="y_slide_0" type="slide" axis="0 1 0" damping="1.0" armature="0.1" limited="false"/>
        <joint name="z_rotate_0" type="hinge" axis="0 0 1" damping="0.5" armature="0.1" limited="false"/>

        <geom name="robot_base_collision_0" type="box" size="0.08 0.10 0.018" pos="0 0 0.018" class="collision" rgba="0.2 0.2 0.8 1" mass="4.9"/> <body name="kicker_body_0" pos="0.08 0 0.018"> <joint name="kicker_slide_0" type="slide" axis="1 0 0" limited="true" range="0 0.05" damping="5" stiffness="0" armature="0.01"/>

            <geom name="kicker_plate_0" type="box" size="0.005 0.0665 0.018" pos="0.005 0 0" class="collision" rgba="1 0.5 0 1" mass="0.1" friction="1.0 0.1 0.1"/>
        </body>
    </body>
    <body name="golf_ball" pos="0 0 0.0115">
        <joint name="ball_joint" type="free"/>
        <geom name="golf_ball_geom" type="sphere" size="0.0115" class="collision" rgba="1 0 0 1" mass="0.046" friction="0.4 0.1 0.1" solref="0.01 1" solimp="0.9 0.98 0.001"/>
    </body>

  </worldbody>

  <actuator>
    <velocity name="x_vel_0" joint="x_slide_0" kv="25" ctrlrange="-3 3"/>
    <velocity name="y_vel_0" joint="y_slide_0" kv="25" ctrlrange="-3 3"/>
    <velocity name="rot_vel_0" joint="z_rotate_0" kv="10" ctrlrange="-5 5"/>

    <position name="kicker_pos_0" joint="kicker_slide_0" kp="1000" kv="20" ctrlrange="0 0.05" ctrllimited="true"/>
  </actuator>

  <contact>
    <pair geom1="robot_base_collision_0" geom2="field"/>
    <pair geom1="kicker_plate_0"       geom2="field"/>
    <pair geom1="golf_ball_geom"         geom2="field"/>

    <pair geom1="kicker_plate_0"       geom2="golf_ball_geom"/>

    <pair geom1="golf_ball_geom" geom2="left_goal_side_top"/>
    <pair geom1="golf_ball_geom" geom2="left_goal_side_bottom"/>
    <pair geom1="golf_ball_geom" geom2="left_goal_backside"/>
    <pair geom1="golf_ball_geom" geom2="right_goal_side_top"/>
    <pair geom1="golf_ball_geom" geom2="right_goal_side_bottom"/>
    <pair geom1="golf_ball_geom" geom2="right_goal_backside"/>

    <pair geom1="robot_base_collision_0" geom2="left_goal_side_top"/>
    <pair geom1="robot_base_collision_0" geom2="left_goal_side_bottom"/>
    <pair geom1="robot_base_collision_0" geom2="left_goal_backside"/>
    <pair geom1="kicker_plate_0"       geom2="left_goal_side_top"/>
    <pair geom1="kicker_plate_0"       geom2="left_goal_side_bottom"/>
    <pair geom1="kicker_plate_0"       geom2="left_goal_backside"/>
    <pair geom1="robot_base_collision_0" geom2="right_goal_side_top"/>
    <pair geom1="robot_base_collision_0" geom2="right_goal_side_bottom"/>
    <pair geom1="robot_base_collision_0" geom2="right_goal_backside"/>
    <pair geom1="kicker_plate_0"       geom2="right_goal_side_top"/>
    <pair geom1="kicker_plate_0"       geom2="right_goal_side_bottom"/>
    <pair geom1="kicker_plate_0"       geom2="right_goal_backside"/>

    <exclude body1="robot_planar_0" body2="kicker_body_0"/>

  </contact>

</mujoco>